{
 "cells": [
  {
   "cell_type": "code",
   "execution_count": 1,
   "metadata": {},
   "outputs": [],
   "source": [
    "import sagemaker\n",
    "\n",
    "sagemaker_session = sagemaker.Session()\n",
    "role = sagemaker.get_execution_role()"
   ]
  },
  {
   "cell_type": "code",
   "execution_count": 20,
   "metadata": {},
   "outputs": [],
   "source": [
    "from sagemaker.pytorch import PyTorch\n",
    "\n",
    "estimator = PyTorch(entry_point='proto_experiment.py',\n",
    "                    source_dir='../few_shot/',\n",
    "                    role=role,\n",
    "                    framework_version='1.2.0',\n",
    "                    train_instance_count=1,\n",
    "                    train_instance_type='ml.c4.2xlarge'\n",
    "                )"
   ]
  },
  {
   "cell_type": "code",
   "execution_count": 21,
   "metadata": {},
   "outputs": [
    {
     "name": "stdout",
     "output_type": "stream",
     "text": [
      "2020-01-12 22:40:17 Starting - Starting the training job...\n",
      "2020-01-12 22:40:18 Starting - Launching requested ML instances...\n",
      "2020-01-12 22:41:17 Starting - Preparing the instances for training......\n",
      "2020-01-12 22:42:07 Downloading - Downloading input data...\n",
      "2020-01-12 22:42:23 Training - Downloading the training image..\u001b[34mbash: cannot set terminal process group (-1): Inappropriate ioctl for device\u001b[0m\n",
      "\u001b[34mbash: no job control in this shell\u001b[0m\n",
      "\u001b[34m2020-01-12 22:42:54,549 sagemaker-containers INFO     Imported framework sagemaker_pytorch_container.training\u001b[0m\n",
      "\u001b[34m2020-01-12 22:42:54,551 sagemaker-containers INFO     No GPUs detected (normal if no gpus installed)\u001b[0m\n",
      "\u001b[34m2020-01-12 22:42:54,563 sagemaker_pytorch_container.training INFO     Block until all host DNS lookups succeed.\u001b[0m\n",
      "\u001b[34m2020-01-12 22:42:57,587 sagemaker_pytorch_container.training INFO     Invoking user training script.\u001b[0m\n",
      "\u001b[34m2020-01-12 22:42:57,968 sagemaker-containers INFO     Module proto_experiment does not provide a setup.py. \u001b[0m\n",
      "\u001b[34mGenerating setup.py\u001b[0m\n",
      "\u001b[34m2020-01-12 22:42:57,968 sagemaker-containers INFO     Generating setup.cfg\u001b[0m\n",
      "\u001b[34m2020-01-12 22:42:57,968 sagemaker-containers INFO     Generating MANIFEST.in\u001b[0m\n",
      "\u001b[34m2020-01-12 22:42:57,969 sagemaker-containers INFO     Installing module with the following command:\u001b[0m\n",
      "\u001b[34m/opt/conda/bin/python -m pip install . -r requirements.txt\u001b[0m\n",
      "\u001b[34mProcessing /opt/ml/code\u001b[0m\n",
      "\u001b[34mCollecting scikit-image==0.14.2\n",
      "  Downloading https://files.pythonhosted.org/packages/24/06/d560630eb9e36d90d69fe57d9ff762d8f501664ce478b8a0ae132b3c3008/scikit_image-0.14.2-cp36-cp36m-manylinux1_x86_64.whl (25.3MB)\u001b[0m\n",
      "\u001b[34mRequirement already satisfied: tqdm==4.36.1 in /opt/conda/lib/python3.6/site-packages (from -r requirements.txt (line 3)) (4.36.1)\u001b[0m\n",
      "\u001b[34mRequirement already satisfied: six>=1.10.0 in /opt/conda/lib/python3.6/site-packages (from scikit-image==0.14.2->-r requirements.txt (line 2)) (1.12.0)\u001b[0m\n",
      "\u001b[34mCollecting dask[array]>=1.0.0\n",
      "  Downloading https://files.pythonhosted.org/packages/3c/d9/2a5860c95a5172b39c28f0f7ccd522a46787bb7e23b7921218d84e81dfb1/dask-2.9.1-py3-none-any.whl (772kB)\u001b[0m\n",
      "\u001b[34mCollecting cloudpickle>=0.2.1\n",
      "  Downloading https://files.pythonhosted.org/packages/c1/49/334e279caa3231255725c8e860fa93e72083567625573421db8875846c14/cloudpickle-1.2.2-py2.py3-none-any.whl\u001b[0m\n",
      "\u001b[34mRequirement already satisfied: scipy>=0.17.0 in /opt/conda/lib/python3.6/site-packages (from scikit-image==0.14.2->-r requirements.txt (line 2)) (1.3.0)\u001b[0m\n",
      "\u001b[34mRequirement already satisfied: pillow>=4.3.0 in /opt/conda/lib/python3.6/site-packages (from scikit-image==0.14.2->-r requirements.txt (line 2)) (6.0.0)\u001b[0m\n",
      "\u001b[34mCollecting PyWavelets>=0.4.0\n",
      "  Downloading https://files.pythonhosted.org/packages/59/bb/d2b85265ec9fa3c1922210c9393d4cdf7075cc87cce6fe671d7455f80fbc/PyWavelets-1.1.1-cp36-cp36m-manylinux1_x86_64.whl (4.4MB)\u001b[0m\n",
      "\u001b[34mRequirement already satisfied: matplotlib>=2.0.0 in /opt/conda/lib/python3.6/site-packages (from scikit-image==0.14.2->-r requirements.txt (line 2)) (3.1.1)\u001b[0m\n",
      "\u001b[34mCollecting networkx>=1.8\n",
      "  Downloading https://files.pythonhosted.org/packages/41/8f/dd6a8e85946def36e4f2c69c84219af0fa5e832b018c970e92f2ad337e45/networkx-2.4-py3-none-any.whl (1.6MB)\u001b[0m\n",
      "\u001b[34mRequirement already satisfied: numpy>=1.13.0; extra == \"array\" in /opt/conda/lib/python3.6/site-packages (from dask[array]>=1.0.0->scikit-image==0.14.2->-r requirements.txt (line 2)) (1.16.4)\u001b[0m\n",
      "\u001b[34mCollecting toolz>=0.7.3; extra == \"array\"\n",
      "  Downloading https://files.pythonhosted.org/packages/22/8e/037b9ba5c6a5739ef0dcde60578c64d49f45f64c5e5e886531bfbc39157f/toolz-0.10.0.tar.gz (49kB)\u001b[0m\n",
      "\u001b[34mRequirement already satisfied: pyparsing!=2.0.4,!=2.1.2,!=2.1.6,>=2.0.1 in /opt/conda/lib/python3.6/site-packages (from matplotlib>=2.0.0->scikit-image==0.14.2->-r requirements.txt (line 2)) (2.4.2)\u001b[0m\n",
      "\u001b[34mRequirement already satisfied: kiwisolver>=1.0.1 in /opt/conda/lib/python3.6/site-packages (from matplotlib>=2.0.0->scikit-image==0.14.2->-r requirements.txt (line 2)) (1.1.0)\u001b[0m\n",
      "\u001b[34mRequirement already satisfied: python-dateutil>=2.1 in /opt/conda/lib/python3.6/site-packages (from matplotlib>=2.0.0->scikit-image==0.14.2->-r requirements.txt (line 2)) (2.8.0)\u001b[0m\n",
      "\u001b[34mRequirement already satisfied: cycler>=0.10 in /opt/conda/lib/python3.6/site-packages (from matplotlib>=2.0.0->scikit-image==0.14.2->-r requirements.txt (line 2)) (0.10.0)\u001b[0m\n",
      "\u001b[34mRequirement already satisfied: decorator>=4.3.0 in /opt/conda/lib/python3.6/site-packages (from networkx>=1.8->scikit-image==0.14.2->-r requirements.txt (line 2)) (4.4.0)\u001b[0m\n",
      "\u001b[34mRequirement already satisfied: setuptools in /opt/conda/lib/python3.6/site-packages (from kiwisolver>=1.0.1->matplotlib>=2.0.0->scikit-image==0.14.2->-r requirements.txt (line 2)) (41.4.0)\u001b[0m\n",
      "\u001b[34mBuilding wheels for collected packages: proto-experiment, toolz\n",
      "  Building wheel for proto-experiment (setup.py): started\u001b[0m\n",
      "\u001b[34m  Building wheel for proto-experiment (setup.py): finished with status 'done'\n",
      "  Created wheel for proto-experiment: filename=proto_experiment-1.0.0-py2.py3-none-any.whl size=21158 sha256=2c680961039b0f5a4f8777b17713cd839924fa3558bfadea61148400764f054f\n",
      "  Stored in directory: /tmp/pip-ephem-wheel-cache-b7740ja7/wheels/35/24/16/37574d11bf9bde50616c67372a334f94fa8356bc7164af8ca3\n",
      "  Building wheel for toolz (setup.py): started\n",
      "  Building wheel for toolz (setup.py): finished with status 'done'\n",
      "  Created wheel for toolz: filename=toolz-0.10.0-cp36-none-any.whl size=55576 sha256=67975af13aa9560097525550c5bf20c1b3aca56a9a2fb22b52a948acf6790a51\n",
      "  Stored in directory: /root/.cache/pip/wheels/e1/8b/65/3294e5b727440250bda09e8c0153b7ba19d328f661605cb151\u001b[0m\n",
      "\u001b[34mSuccessfully built proto-experiment toolz\u001b[0m\n",
      "\u001b[34mInstalling collected packages: toolz, dask, cloudpickle, PyWavelets, networkx, scikit-image, proto-experiment\u001b[0m\n",
      "\u001b[34mSuccessfully installed PyWavelets-1.1.1 cloudpickle-1.2.2 dask-2.9.1 networkx-2.4 proto-experiment-1.0.0 scikit-image-0.14.2 toolz-0.10.0\u001b[0m\n",
      "\u001b[34mWARNING: You are using pip version 19.3; however, version 19.3.1 is available.\u001b[0m\n",
      "\u001b[34mYou should consider upgrading via the 'pip install --upgrade pip' command.\u001b[0m\n",
      "\u001b[34m2020-01-12 22:43:04,298 sagemaker-containers INFO     No GPUs detected (normal if no gpus installed)\u001b[0m\n",
      "\u001b[34m2020-01-12 22:43:04,310 sagemaker-containers INFO     Invoking user script\n",
      "\u001b[0m\n",
      "\u001b[34mTraining Env:\n",
      "\u001b[0m\n",
      "\u001b[34m{\n",
      "    \"additional_framework_parameters\": {},\n",
      "    \"channel_input_dirs\": {\n",
      "        \"test\": \"/opt/ml/input/data/test\",\n",
      "        \"train\": \"/opt/ml/input/data/train\"\n",
      "    },\n",
      "    \"current_host\": \"algo-1\",\n",
      "    \"framework_module\": \"sagemaker_pytorch_container.training:main\",\n",
      "    \"hosts\": [\n",
      "        \"algo-1\"\n",
      "    ],\n",
      "    \"hyperparameters\": {},\n",
      "    \"input_config_dir\": \"/opt/ml/input/config\",\n",
      "    \"input_data_config\": {\n",
      "        \"test\": {\n",
      "            \"TrainingInputMode\": \"File\",\n",
      "            \"S3DistributionType\": \"FullyReplicated\",\n",
      "            \"RecordWrapperType\": \"None\"\n",
      "        },\n",
      "        \"train\": {\n",
      "            \"TrainingInputMode\": \"File\",\n",
      "            \"S3DistributionType\": \"FullyReplicated\",\n",
      "            \"RecordWrapperType\": \"None\"\n",
      "        }\n",
      "    },\n",
      "    \"input_dir\": \"/opt/ml/input\",\n",
      "    \"is_master\": true,\n",
      "    \"job_name\": \"pytorch-training-2020-01-12-22-40-16-431\",\n",
      "    \"log_level\": 20,\n",
      "    \"master_hostname\": \"algo-1\",\n",
      "    \"model_dir\": \"/opt/ml/model\",\n",
      "    \"module_dir\": \"s3://sagemaker-eu-west-1-175716149256/pytorch-training-2020-01-12-22-40-16-431/source/sourcedir.tar.gz\",\n",
      "    \"module_name\": \"proto_experiment\",\n",
      "    \"network_interface_name\": \"eth0\",\n",
      "    \"num_cpus\": 8,\n",
      "    \"num_gpus\": 0,\n",
      "    \"output_data_dir\": \"/opt/ml/output/data\",\n",
      "    \"output_dir\": \"/opt/ml/output\",\n",
      "    \"output_intermediate_dir\": \"/opt/ml/output/intermediate\",\n",
      "    \"resource_config\": {\n",
      "        \"current_host\": \"algo-1\",\n",
      "        \"hosts\": [\n",
      "            \"algo-1\"\n",
      "        ],\n",
      "        \"network_interface_name\": \"eth0\"\n",
      "    },\n",
      "    \"user_entry_point\": \"proto_experiment.py\"\u001b[0m\n",
      "\u001b[34m}\n",
      "\u001b[0m\n",
      "\u001b[34mEnvironment variables:\n",
      "\u001b[0m\n",
      "\u001b[34mSM_HOSTS=[\"algo-1\"]\u001b[0m\n",
      "\u001b[34mSM_NETWORK_INTERFACE_NAME=eth0\u001b[0m\n",
      "\u001b[34mSM_HPS={}\u001b[0m\n",
      "\u001b[34mSM_USER_ENTRY_POINT=proto_experiment.py\u001b[0m\n",
      "\u001b[34mSM_FRAMEWORK_PARAMS={}\u001b[0m\n",
      "\u001b[34mSM_RESOURCE_CONFIG={\"current_host\":\"algo-1\",\"hosts\":[\"algo-1\"],\"network_interface_name\":\"eth0\"}\u001b[0m\n",
      "\u001b[34mSM_INPUT_DATA_CONFIG={\"test\":{\"RecordWrapperType\":\"None\",\"S3DistributionType\":\"FullyReplicated\",\"TrainingInputMode\":\"File\"},\"train\":{\"RecordWrapperType\":\"None\",\"S3DistributionType\":\"FullyReplicated\",\"TrainingInputMode\":\"File\"}}\u001b[0m\n",
      "\u001b[34mSM_OUTPUT_DATA_DIR=/opt/ml/output/data\u001b[0m\n",
      "\u001b[34mSM_CHANNELS=[\"test\",\"train\"]\u001b[0m\n",
      "\u001b[34mSM_CURRENT_HOST=algo-1\u001b[0m\n",
      "\u001b[34mSM_MODULE_NAME=proto_experiment\u001b[0m\n",
      "\u001b[34mSM_LOG_LEVEL=20\u001b[0m\n",
      "\u001b[34mSM_FRAMEWORK_MODULE=sagemaker_pytorch_container.training:main\u001b[0m\n",
      "\u001b[34mSM_INPUT_DIR=/opt/ml/input\u001b[0m\n",
      "\u001b[34mSM_INPUT_CONFIG_DIR=/opt/ml/input/config\u001b[0m\n",
      "\u001b[34mSM_OUTPUT_DIR=/opt/ml/output\u001b[0m\n",
      "\u001b[34mSM_NUM_CPUS=8\u001b[0m\n",
      "\u001b[34mSM_NUM_GPUS=0\u001b[0m\n",
      "\u001b[34mSM_MODEL_DIR=/opt/ml/model\u001b[0m\n",
      "\u001b[34mSM_MODULE_DIR=s3://sagemaker-eu-west-1-175716149256/pytorch-training-2020-01-12-22-40-16-431/source/sourcedir.tar.gz\u001b[0m\n",
      "\u001b[34mSM_TRAINING_ENV={\"additional_framework_parameters\":{},\"channel_input_dirs\":{\"test\":\"/opt/ml/input/data/test\",\"train\":\"/opt/ml/input/data/train\"},\"current_host\":\"algo-1\",\"framework_module\":\"sagemaker_pytorch_container.training:main\",\"hosts\":[\"algo-1\"],\"hyperparameters\":{},\"input_config_dir\":\"/opt/ml/input/config\",\"input_data_config\":{\"test\":{\"RecordWrapperType\":\"None\",\"S3DistributionType\":\"FullyReplicated\",\"TrainingInputMode\":\"File\"},\"train\":{\"RecordWrapperType\":\"None\",\"S3DistributionType\":\"FullyReplicated\",\"TrainingInputMode\":\"File\"}},\"input_dir\":\"/opt/ml/input\",\"is_master\":true,\"job_name\":\"pytorch-training-2020-01-12-22-40-16-431\",\"log_level\":20,\"master_hostname\":\"algo-1\",\"model_dir\":\"/opt/ml/model\",\"module_dir\":\"s3://sagemaker-eu-west-1-175716149256/pytorch-training-2020-01-12-22-40-16-431/source/sourcedir.tar.gz\",\"module_name\":\"proto_experiment\",\"network_interface_name\":\"eth0\",\"num_cpus\":8,\"num_gpus\":0,\"output_data_dir\":\"/opt/ml/output/data\",\"output_dir\":\"/opt/ml/output\",\"output_intermediate_dir\":\"/opt/ml/output/intermediate\",\"resource_config\":{\"current_host\":\"algo-1\",\"hosts\":[\"algo-1\"],\"network_interface_name\":\"eth0\"},\"user_entry_point\":\"proto_experiment.py\"}\u001b[0m\n",
      "\u001b[34mSM_USER_ARGS=[]\u001b[0m\n",
      "\u001b[34mSM_OUTPUT_INTERMEDIATE_DIR=/opt/ml/output/intermediate\u001b[0m\n",
      "\u001b[34mSM_CHANNEL_TEST=/opt/ml/input/data/test\u001b[0m\n",
      "\u001b[34mSM_CHANNEL_TRAIN=/opt/ml/input/data/train\u001b[0m\n",
      "\u001b[34mPYTHONPATH=/opt/conda/bin:/opt/conda/lib/python36.zip:/opt/conda/lib/python3.6:/opt/conda/lib/python3.6/lib-dynload:/opt/conda/lib/python3.6/site-packages\n",
      "\u001b[0m\n",
      "\u001b[34mInvoking script with the following command:\n",
      "\u001b[0m\n",
      "\u001b[34m/opt/conda/bin/python -m proto_experiment\n",
      "\n",
      "\u001b[0m\n",
      "\n",
      "2020-01-12 22:42:53 Training - Training image download completed. Training in progress.\u001b[34mstart unzipping images_background.zip\u001b[0m\n",
      "\u001b[34m/opt/ml/input/data/train/images_background.zip\u001b[0m\n",
      "\u001b[34m['images_background.zip']\u001b[0m\n",
      "\u001b[34mIndexing background...\u001b[0m\n",
      "\u001b[34m2020-01-12 22:43:15,476 sagemaker-containers ERROR    ExecuteUserScriptError:\u001b[0m\n",
      "\u001b[34mCommand \"/opt/conda/bin/python -m proto_experiment\"\u001b[0m\n",
      "\u001b[34m#0150it [00:00, ?it/s]#0150it [00:00, ?it/s]\u001b[0m\n",
      "\u001b[34mTraceback (most recent call last):\n",
      "  File \"/opt/conda/lib/python3.6/site-packages/pandas/core/indexes/base.py\", line 2890, in get_loc\n",
      "    return self._engine.get_loc(key)\n",
      "  File \"pandas/_libs/index.pyx\", line 107, in pandas._libs.index.IndexEngine.get_loc\n",
      "  File \"pandas/_libs/index.pyx\", line 131, in pandas._libs.index.IndexEngine.get_loc\n",
      "  File \"pandas/_libs/hashtable_class_helper.pxi\", line 1607, in pandas._libs.hashtable.PyObjectHashTable.get_item\n",
      "  File \"pandas/_libs/hashtable_class_helper.pxi\", line 1614, in pandas._libs.hashtable.PyObjectHashTable.get_item\u001b[0m\n",
      "\u001b[34mKeyError: 'class_name'\n",
      "\u001b[0m\n",
      "\u001b[34mDuring handling of the above exception, another exception occurred:\n",
      "\u001b[0m\n",
      "\u001b[34mTraceback (most recent call last):\n",
      "  File \"/opt/conda/lib/python3.6/runpy.py\", line 193, in _run_module_as_main\n",
      "    \"__main__\", mod_spec)\n",
      "  File \"/opt/conda/lib/python3.6/runpy.py\", line 85, in _run_code\n",
      "    exec(code, run_globals)\n",
      "  File \"/opt/ml/code/proto_experiment.py\", line 124, in <module>\n",
      "    Initialise_training(args)\n",
      "  File \"/opt/ml/code/proto_experiment.py\", line 26, in Initialise_training\n",
      "    background = OmniglotDataset('background', args.data_train, unzip=True)\n",
      "  File \"/opt/ml/code/meta_learning/data_processing/datasets.py\", line 101, in __init__\n",
      "    super(OmniglotDataset, self).__init__(self.subset, self.data_path, unzip)\n",
      "  File \"/opt/ml/code/meta_learning/data_processing/datasets.py\", line 32, in __init__\n",
      "    self.unique_characters = sorted(self.df['class_name'].unique())\n",
      "  File \"/opt/conda/lib/python3.6/site-packages/pandas/core/frame.py\", line 2975, in __getitem__\n",
      "    indexer = self.columns.get_loc(key)\n",
      "  File \"/opt/conda/lib/python3.6/site-packages/pandas/core/indexes/base.py\", line 2892, in get_loc\n",
      "    return self._engine.get_loc(self._maybe_cast_indexer(key))\n",
      "  File \"pandas/_libs/index.pyx\", line 107, in pandas._libs.index.IndexEngine.get_loc\n",
      "  File \"pandas/_libs/index.pyx\", line 131, in pandas._libs.index.IndexEngine.get_loc\n",
      "  File \"pandas/_libs/hashtable_class_helper.pxi\", line 1607, in pandas._libs.hashtable.PyObjectHashTable.get_item\n",
      "  File \"pandas/_libs/hashtable_class_helper.pxi\", line 1614, in pandas._libs.hashtable.PyObjectHashTable.get_item\u001b[0m\n",
      "\u001b[34mKeyError: 'class_name'\u001b[0m\n",
      "\n",
      "2020-01-12 22:43:19 Uploading - Uploading generated training model\n",
      "2020-01-12 22:43:50 Failed - Training job failed\n"
     ]
    },
    {
     "ename": "UnexpectedStatusException",
     "evalue": "Error for Training job pytorch-training-2020-01-12-22-40-16-431: Failed. Reason: AlgorithmError: ExecuteUserScriptError:\nCommand \"/opt/conda/bin/python -m proto_experiment\"\n\r0it [00:00, ?it/s]\r0it [00:00, ?it/s]\nTraceback (most recent call last):\n  File \"/opt/conda/lib/python3.6/site-packages/pandas/core/indexes/base.py\", line 2890, in get_loc\n    return self._engine.get_loc(key)\n  File \"pandas/_libs/index.pyx\", line 107, in pandas._libs.index.IndexEngine.get_loc\n  File \"pandas/_libs/index.pyx\", line 131, in pandas._libs.index.IndexEngine.get_loc\n  File \"pandas/_libs/hashtable_class_helper.pxi\", line 1607, in pandas._libs.hashtable.PyObjectHashTable.get_item\n  File \"pandas/_libs/hashtable_class_helper.pxi\", line 1614, in pandas._libs.hashtable.PyObjectHashTable.get_item\nKeyError: 'class_name'\n\nDuring handling of the above exception, another exception occurred:\n\nTraceback (most recent call last):\n  File \"/opt/conda/lib/python3.6/runpy.py\", line 193, in _run_module_as_main\n    \"__main__\", mod_spec)\n  File \"/opt/conda/lib/python3.6/runpy.py\", line 85, in _run_code\n    exec(code, run_globals)",
     "output_type": "error",
     "traceback": [
      "\u001b[0;31m---------------------------------------------------------------------------\u001b[0m",
      "\u001b[0;31mUnexpectedStatusException\u001b[0m                 Traceback (most recent call last)",
      "\u001b[0;32m<ipython-input-21-f611566cf731>\u001b[0m in \u001b[0;36m<module>\u001b[0;34m()\u001b[0m\n\u001b[1;32m      1\u001b[0m estimator.fit({'train':'s3://test-meta-learning-data/data/omniglot/images_background.zip',\n\u001b[0;32m----> 2\u001b[0;31m                'test':'s3://test-meta-learning-data/data/omniglot/images_evaluation.zip'})\n\u001b[0m",
      "\u001b[0;32m~/anaconda3/envs/pytorch_p36/lib/python3.6/site-packages/sagemaker/estimator.py\u001b[0m in \u001b[0;36mfit\u001b[0;34m(self, inputs, wait, logs, job_name, experiment_config)\u001b[0m\n\u001b[1;32m    462\u001b[0m         \u001b[0mself\u001b[0m\u001b[0;34m.\u001b[0m\u001b[0mjobs\u001b[0m\u001b[0;34m.\u001b[0m\u001b[0mappend\u001b[0m\u001b[0;34m(\u001b[0m\u001b[0mself\u001b[0m\u001b[0;34m.\u001b[0m\u001b[0mlatest_training_job\u001b[0m\u001b[0;34m)\u001b[0m\u001b[0;34m\u001b[0m\u001b[0m\n\u001b[1;32m    463\u001b[0m         \u001b[0;32mif\u001b[0m \u001b[0mwait\u001b[0m\u001b[0;34m:\u001b[0m\u001b[0;34m\u001b[0m\u001b[0m\n\u001b[0;32m--> 464\u001b[0;31m             \u001b[0mself\u001b[0m\u001b[0;34m.\u001b[0m\u001b[0mlatest_training_job\u001b[0m\u001b[0;34m.\u001b[0m\u001b[0mwait\u001b[0m\u001b[0;34m(\u001b[0m\u001b[0mlogs\u001b[0m\u001b[0;34m=\u001b[0m\u001b[0mlogs\u001b[0m\u001b[0;34m)\u001b[0m\u001b[0;34m\u001b[0m\u001b[0m\n\u001b[0m\u001b[1;32m    465\u001b[0m \u001b[0;34m\u001b[0m\u001b[0m\n\u001b[1;32m    466\u001b[0m     \u001b[0;32mdef\u001b[0m \u001b[0m_compilation_job_name\u001b[0m\u001b[0;34m(\u001b[0m\u001b[0mself\u001b[0m\u001b[0;34m)\u001b[0m\u001b[0;34m:\u001b[0m\u001b[0;34m\u001b[0m\u001b[0m\n",
      "\u001b[0;32m~/anaconda3/envs/pytorch_p36/lib/python3.6/site-packages/sagemaker/estimator.py\u001b[0m in \u001b[0;36mwait\u001b[0;34m(self, logs)\u001b[0m\n\u001b[1;32m   1059\u001b[0m         \u001b[0;31m# If logs are requested, call logs_for_jobs.\u001b[0m\u001b[0;34m\u001b[0m\u001b[0;34m\u001b[0m\u001b[0m\n\u001b[1;32m   1060\u001b[0m         \u001b[0;32mif\u001b[0m \u001b[0mlogs\u001b[0m \u001b[0;34m!=\u001b[0m \u001b[0;34m\"None\"\u001b[0m\u001b[0;34m:\u001b[0m\u001b[0;34m\u001b[0m\u001b[0m\n\u001b[0;32m-> 1061\u001b[0;31m             \u001b[0mself\u001b[0m\u001b[0;34m.\u001b[0m\u001b[0msagemaker_session\u001b[0m\u001b[0;34m.\u001b[0m\u001b[0mlogs_for_job\u001b[0m\u001b[0;34m(\u001b[0m\u001b[0mself\u001b[0m\u001b[0;34m.\u001b[0m\u001b[0mjob_name\u001b[0m\u001b[0;34m,\u001b[0m \u001b[0mwait\u001b[0m\u001b[0;34m=\u001b[0m\u001b[0;32mTrue\u001b[0m\u001b[0;34m,\u001b[0m \u001b[0mlog_type\u001b[0m\u001b[0;34m=\u001b[0m\u001b[0mlogs\u001b[0m\u001b[0;34m)\u001b[0m\u001b[0;34m\u001b[0m\u001b[0m\n\u001b[0m\u001b[1;32m   1062\u001b[0m         \u001b[0;32melse\u001b[0m\u001b[0;34m:\u001b[0m\u001b[0;34m\u001b[0m\u001b[0m\n\u001b[1;32m   1063\u001b[0m             \u001b[0mself\u001b[0m\u001b[0;34m.\u001b[0m\u001b[0msagemaker_session\u001b[0m\u001b[0;34m.\u001b[0m\u001b[0mwait_for_job\u001b[0m\u001b[0;34m(\u001b[0m\u001b[0mself\u001b[0m\u001b[0;34m.\u001b[0m\u001b[0mjob_name\u001b[0m\u001b[0;34m)\u001b[0m\u001b[0;34m\u001b[0m\u001b[0m\n",
      "\u001b[0;32m~/anaconda3/envs/pytorch_p36/lib/python3.6/site-packages/sagemaker/session.py\u001b[0m in \u001b[0;36mlogs_for_job\u001b[0;34m(self, job_name, wait, poll, log_type)\u001b[0m\n\u001b[1;32m   2972\u001b[0m \u001b[0;34m\u001b[0m\u001b[0m\n\u001b[1;32m   2973\u001b[0m         \u001b[0;32mif\u001b[0m \u001b[0mwait\u001b[0m\u001b[0;34m:\u001b[0m\u001b[0;34m\u001b[0m\u001b[0m\n\u001b[0;32m-> 2974\u001b[0;31m             \u001b[0mself\u001b[0m\u001b[0;34m.\u001b[0m\u001b[0m_check_job_status\u001b[0m\u001b[0;34m(\u001b[0m\u001b[0mjob_name\u001b[0m\u001b[0;34m,\u001b[0m \u001b[0mdescription\u001b[0m\u001b[0;34m,\u001b[0m \u001b[0;34m\"TrainingJobStatus\"\u001b[0m\u001b[0;34m)\u001b[0m\u001b[0;34m\u001b[0m\u001b[0m\n\u001b[0m\u001b[1;32m   2975\u001b[0m             \u001b[0;32mif\u001b[0m \u001b[0mdot\u001b[0m\u001b[0;34m:\u001b[0m\u001b[0;34m\u001b[0m\u001b[0m\n\u001b[1;32m   2976\u001b[0m                 \u001b[0mprint\u001b[0m\u001b[0;34m(\u001b[0m\u001b[0;34m)\u001b[0m\u001b[0;34m\u001b[0m\u001b[0m\n",
      "\u001b[0;32m~/anaconda3/envs/pytorch_p36/lib/python3.6/site-packages/sagemaker/session.py\u001b[0m in \u001b[0;36m_check_job_status\u001b[0;34m(self, job, desc, status_key_name)\u001b[0m\n\u001b[1;32m   2566\u001b[0m                 ),\n\u001b[1;32m   2567\u001b[0m                 \u001b[0mallowed_statuses\u001b[0m\u001b[0;34m=\u001b[0m\u001b[0;34m[\u001b[0m\u001b[0;34m\"Completed\"\u001b[0m\u001b[0;34m,\u001b[0m \u001b[0;34m\"Stopped\"\u001b[0m\u001b[0;34m]\u001b[0m\u001b[0;34m,\u001b[0m\u001b[0;34m\u001b[0m\u001b[0m\n\u001b[0;32m-> 2568\u001b[0;31m                 \u001b[0mactual_status\u001b[0m\u001b[0;34m=\u001b[0m\u001b[0mstatus\u001b[0m\u001b[0;34m,\u001b[0m\u001b[0;34m\u001b[0m\u001b[0m\n\u001b[0m\u001b[1;32m   2569\u001b[0m             )\n\u001b[1;32m   2570\u001b[0m \u001b[0;34m\u001b[0m\u001b[0m\n",
      "\u001b[0;31mUnexpectedStatusException\u001b[0m: Error for Training job pytorch-training-2020-01-12-22-40-16-431: Failed. Reason: AlgorithmError: ExecuteUserScriptError:\nCommand \"/opt/conda/bin/python -m proto_experiment\"\n\r0it [00:00, ?it/s]\r0it [00:00, ?it/s]\nTraceback (most recent call last):\n  File \"/opt/conda/lib/python3.6/site-packages/pandas/core/indexes/base.py\", line 2890, in get_loc\n    return self._engine.get_loc(key)\n  File \"pandas/_libs/index.pyx\", line 107, in pandas._libs.index.IndexEngine.get_loc\n  File \"pandas/_libs/index.pyx\", line 131, in pandas._libs.index.IndexEngine.get_loc\n  File \"pandas/_libs/hashtable_class_helper.pxi\", line 1607, in pandas._libs.hashtable.PyObjectHashTable.get_item\n  File \"pandas/_libs/hashtable_class_helper.pxi\", line 1614, in pandas._libs.hashtable.PyObjectHashTable.get_item\nKeyError: 'class_name'\n\nDuring handling of the above exception, another exception occurred:\n\nTraceback (most recent call last):\n  File \"/opt/conda/lib/python3.6/runpy.py\", line 193, in _run_module_as_main\n    \"__main__\", mod_spec)\n  File \"/opt/conda/lib/python3.6/runpy.py\", line 85, in _run_code\n    exec(code, run_globals)"
     ]
    }
   ],
   "source": [
    "estimator.fit({'train':'s3://test-meta-learning-data/data/omniglot/images_background.zip',\n",
    "               'test':'s3://test-meta-learning-data/data/omniglot/images_evaluation.zip'})"
   ]
  },
  {
   "cell_type": "code",
   "execution_count": null,
   "metadata": {},
   "outputs": [],
   "source": []
  }
 ],
 "metadata": {
  "kernelspec": {
   "display_name": "conda_pytorch_p36",
   "language": "python",
   "name": "conda_pytorch_p36"
  },
  "language_info": {
   "codemirror_mode": {
    "name": "ipython",
    "version": 3
   },
   "file_extension": ".py",
   "mimetype": "text/x-python",
   "name": "python",
   "nbconvert_exporter": "python",
   "pygments_lexer": "ipython3",
   "version": "3.6.5"
  }
 },
 "nbformat": 4,
 "nbformat_minor": 4
}
